{
 "cells": [
  {
   "cell_type": "code",
   "id": "initial_id",
   "metadata": {
    "collapsed": true,
    "ExecuteTime": {
     "end_time": "2025-06-06T14:23:36.822231Z",
     "start_time": "2025-06-06T14:23:36.801234Z"
    }
   },
   "source": [
    "\n",
    "# Install with pip install firecrawl-py\n",
    "import asyncio\n",
    "from firecrawl import AsyncFirecrawlApp\n",
    "\n",
    "async def get_data(app: AsyncFirecrawlApp):\n",
    "    return await app.scrape_url(\n",
    "        url='https://bloodhound.specterops.io',\n",
    "        formats= [ 'markdown', 'links', 'screenshot@fullPage' ],\n",
    "        only_main_content= True,\n",
    "        proxy= \"stealth\"\n",
    "    )\n",
    "\n",
    "def main():\n",
    "    app = AsyncFirecrawlApp(api_key='fc-8aabe9f9bb4b429f8b1eb0593b68368b')\n",
    "    response = get_data(app)\n",
    "\n",
    "if __name__ == '__main__':\n",
    "    asyncio.run(main())"
   ],
   "outputs": [
    {
     "name": "stderr",
     "output_type": "stream",
     "text": [
      "/var/folders/s5/347vw0qn79q6zvw60c817hxr0000gn/T/ipykernel_80455/3154089849.py:18: RuntimeWarning: coroutine 'get_data' was never awaited\n",
      "  asyncio.run(main())\n",
      "RuntimeWarning: Enable tracemalloc to get the object allocation traceback\n"
     ]
    },
    {
     "ename": "RuntimeError",
     "evalue": "asyncio.run() cannot be called from a running event loop",
     "output_type": "error",
     "traceback": [
      "\u001B[31m---------------------------------------------------------------------------\u001B[39m",
      "\u001B[31mRuntimeError\u001B[39m                              Traceback (most recent call last)",
      "\u001B[36mCell\u001B[39m\u001B[36m \u001B[39m\u001B[32mIn[12]\u001B[39m\u001B[32m, line 18\u001B[39m\n\u001B[32m     15\u001B[39m     response = get_data(app)\n\u001B[32m     17\u001B[39m \u001B[38;5;28;01mif\u001B[39;00m \u001B[34m__name__\u001B[39m == \u001B[33m'\u001B[39m\u001B[33m__main__\u001B[39m\u001B[33m'\u001B[39m:\n\u001B[32m---> \u001B[39m\u001B[32m18\u001B[39m     \u001B[43masyncio\u001B[49m\u001B[43m.\u001B[49m\u001B[43mrun\u001B[49m\u001B[43m(\u001B[49m\u001B[43mmain\u001B[49m\u001B[43m(\u001B[49m\u001B[43m)\u001B[49m\u001B[43m)\u001B[49m\n",
      "\u001B[36mFile \u001B[39m\u001B[32m/Library/Frameworks/Python.framework/Versions/3.11/lib/python3.11/asyncio/runners.py:186\u001B[39m, in \u001B[36mrun\u001B[39m\u001B[34m(main, debug)\u001B[39m\n\u001B[32m    161\u001B[39m \u001B[38;5;250m\u001B[39m\u001B[33;03m\"\"\"Execute the coroutine and return the result.\u001B[39;00m\n\u001B[32m    162\u001B[39m \n\u001B[32m    163\u001B[39m \u001B[33;03mThis function runs the passed coroutine, taking care of\u001B[39;00m\n\u001B[32m   (...)\u001B[39m\u001B[32m    182\u001B[39m \u001B[33;03m    asyncio.run(main())\u001B[39;00m\n\u001B[32m    183\u001B[39m \u001B[33;03m\"\"\"\u001B[39;00m\n\u001B[32m    184\u001B[39m \u001B[38;5;28;01mif\u001B[39;00m events._get_running_loop() \u001B[38;5;129;01mis\u001B[39;00m \u001B[38;5;129;01mnot\u001B[39;00m \u001B[38;5;28;01mNone\u001B[39;00m:\n\u001B[32m    185\u001B[39m     \u001B[38;5;66;03m# fail fast with short traceback\u001B[39;00m\n\u001B[32m--> \u001B[39m\u001B[32m186\u001B[39m     \u001B[38;5;28;01mraise\u001B[39;00m \u001B[38;5;167;01mRuntimeError\u001B[39;00m(\n\u001B[32m    187\u001B[39m         \u001B[33m\"\u001B[39m\u001B[33masyncio.run() cannot be called from a running event loop\u001B[39m\u001B[33m\"\u001B[39m)\n\u001B[32m    189\u001B[39m \u001B[38;5;28;01mwith\u001B[39;00m Runner(debug=debug) \u001B[38;5;28;01mas\u001B[39;00m runner:\n\u001B[32m    190\u001B[39m     \u001B[38;5;28;01mreturn\u001B[39;00m runner.run(main)\n",
      "\u001B[31mRuntimeError\u001B[39m: asyncio.run() cannot be called from a running event loop"
     ]
    }
   ],
   "execution_count": 12
  },
  {
   "metadata": {
    "ExecuteTime": {
     "end_time": "2025-06-06T14:20:22.679849Z",
     "start_time": "2025-06-06T14:20:22.655048Z"
    }
   },
   "cell_type": "code",
   "source": "",
   "id": "6371d35cea3fb303",
   "outputs": [
    {
     "ename": "RuntimeError",
     "evalue": "asyncio.run() cannot be called from a running event loop",
     "output_type": "error",
     "traceback": [
      "\u001B[31m---------------------------------------------------------------------------\u001B[39m",
      "\u001B[31mRuntimeError\u001B[39m                              Traceback (most recent call last)",
      "\u001B[36mCell\u001B[39m\u001B[36m \u001B[39m\u001B[32mIn[4]\u001B[39m\u001B[32m, line 1\u001B[39m\n\u001B[32m----> \u001B[39m\u001B[32m1\u001B[39m results = \u001B[38;5;28;01mawait\u001B[39;00m \u001B[43masyncio\u001B[49m\u001B[43m.\u001B[49m\u001B[43mrun\u001B[49m\u001B[43m(\u001B[49m\u001B[43mmain\u001B[49m\u001B[43m(\u001B[49m\u001B[43m)\u001B[49m\u001B[43m)\u001B[49m\n",
      "\u001B[36mFile \u001B[39m\u001B[32m/Library/Frameworks/Python.framework/Versions/3.11/lib/python3.11/asyncio/runners.py:186\u001B[39m, in \u001B[36mrun\u001B[39m\u001B[34m(main, debug)\u001B[39m\n\u001B[32m    161\u001B[39m \u001B[38;5;250m\u001B[39m\u001B[33;03m\"\"\"Execute the coroutine and return the result.\u001B[39;00m\n\u001B[32m    162\u001B[39m \n\u001B[32m    163\u001B[39m \u001B[33;03mThis function runs the passed coroutine, taking care of\u001B[39;00m\n\u001B[32m   (...)\u001B[39m\u001B[32m    182\u001B[39m \u001B[33;03m    asyncio.run(main())\u001B[39;00m\n\u001B[32m    183\u001B[39m \u001B[33;03m\"\"\"\u001B[39;00m\n\u001B[32m    184\u001B[39m \u001B[38;5;28;01mif\u001B[39;00m events._get_running_loop() \u001B[38;5;129;01mis\u001B[39;00m \u001B[38;5;129;01mnot\u001B[39;00m \u001B[38;5;28;01mNone\u001B[39;00m:\n\u001B[32m    185\u001B[39m     \u001B[38;5;66;03m# fail fast with short traceback\u001B[39;00m\n\u001B[32m--> \u001B[39m\u001B[32m186\u001B[39m     \u001B[38;5;28;01mraise\u001B[39;00m \u001B[38;5;167;01mRuntimeError\u001B[39;00m(\n\u001B[32m    187\u001B[39m         \u001B[33m\"\u001B[39m\u001B[33masyncio.run() cannot be called from a running event loop\u001B[39m\u001B[33m\"\u001B[39m)\n\u001B[32m    189\u001B[39m \u001B[38;5;28;01mwith\u001B[39;00m Runner(debug=debug) \u001B[38;5;28;01mas\u001B[39;00m runner:\n\u001B[32m    190\u001B[39m     \u001B[38;5;28;01mreturn\u001B[39;00m runner.run(main)\n",
      "\u001B[31mRuntimeError\u001B[39m: asyncio.run() cannot be called from a running event loop"
     ]
    }
   ],
   "execution_count": 4
  },
  {
   "metadata": {},
   "cell_type": "code",
   "outputs": [],
   "execution_count": null,
   "source": "",
   "id": "29bc9c0f285e952f"
  }
 ],
 "metadata": {
  "kernelspec": {
   "display_name": "Python 3",
   "language": "python",
   "name": "python3"
  },
  "language_info": {
   "codemirror_mode": {
    "name": "ipython",
    "version": 2
   },
   "file_extension": ".py",
   "mimetype": "text/x-python",
   "name": "python",
   "nbconvert_exporter": "python",
   "pygments_lexer": "ipython2",
   "version": "2.7.6"
  }
 },
 "nbformat": 4,
 "nbformat_minor": 5
}
